Workbook
Name NativeTimeline_Date: #N/A
Name Slicer_Months__Date: #N/A
Name Slicer_Years__Date: #N/A

Sheet RAW_DATA
A1: Date | B1: Children apprehended and placed in CBP custody* | C1: Children in CBP custody | D1: Children transferred out of CBP custody | E1: Children in HHS Care | F1: Children discharged from HHS Care
A2: December 21, 2025 | B2: 6 | C2: 18 | D2: 11 | E2: 2484 | F2: 14
A3: December 18, 2025 | B3: 11 | C3: 50 | D3: 6 | E3: 2472 | F3: 16
A4: December 17, 2025 | B4: 7 | C4: 31 | D4: 11 | E4: 2481 | F4: 10
A5: December 16, 2025 | B5: 8 | C5: 54 | D5: 15 | E5: 2468 | F5: 9
A6: December 15, 2025 | B6: 11 | C6: 42 | D6: 9 | E6: 2470 | F6: 7
A7: December 14, 2025 | B7: 8 | C7: 35 | D7: 4 | E7: 2462 | F7: 8
A8: December 11, 2025 | B8: 7 | C8: 47 | D8: 9 | E8: 2437 | F8: 10
A9: December 10, 2025 | B9: 10 | C9: 54 | D9: 5 | E9: 2439 | F9: 9
A10: December 09, 2025 | B10: 4 | C10: 30 | D10: 7 | E10: 2443 | F10: 8
A11: December 08, 2025 | B11: 9 | C11: 27 | D11: 9 | E11: 2440 | F11: 4
A12: December 07, 2025 | B12: 4 | C12: 24 | D12: 13 | E12: 2429 | F12: 12
A13: December 04, 2025 | B13: 16 | C13: 39 | D13: 7 | E13: 2418 | F13: 13
... A721: January 12, 2023 | B721: 33 | C721: 53 | D721: 34 | E721: 6566 | F721: 436

Sheet CLEAN_DATA
A1: Date | B1: Children_Apprehended | C1: Children in CBP custody | D1: Children transferred out of CBP custody | E1: Children in HHS Care | F1: Children discharged from HHS Care
A2: 46012 | B2: 6 | C2: 18 | D2: 11 | E2: 2484 | F2: 14
A3: 46009 | B3: 11 | C3: 50 | D3: 6 | E3: 2472 | F3: 16
A4: 46008 | B4: 7 | C4: 31 | D4: 11 | E4: 2481 | F4: 10
A5: 46007 | B5: 8 | C5: 54 | D5: 15 | E5: 2468 | F5: 9
A6: 46006 | B6: 11 | C6: 42 | D6: 9 | E6: 2470 | F6: 7
A7: 46005 | B7: 8 | C7: 35 | D7: 4 | E7: 2462 | F7: 8
A8: 46002 | B8: 7 | C8: 47 | D8: 9 | E8: 2437 | F8: 10
A9: 46001 | B9: 10 | C9: 54 | D9: 5 | E9: 2439 | F9: 9
A10: 46000 | B10: 4 | C10: 30 | D10: 7 | E10: 2443 | F10: 8
A11: 45999 | B11: 9 | C11: 27 | D11: 9 | E11: 2440 | F11: 4
A12: 45998 | B12: 4 | C12: 24 | D12: 13 | E12: 2429 | F12: 12
A13: 45995 | B13: 16 | C13: 39 | D13: 7 | E13: 2418 | F13: 13
... A56: 45931 | B56: 4 | C56: 33 | D56: 12 | E56: 2163 | F56: 14
A57: 45807 | B57: 30, | C57: 2025 | D57: 12 | E57: 2159 | F57: 7
A58: =A57-1 -> 45806 | B58: 29, | C58: 2025 | D58: 12 | E58: 2148 | F58: 13
A59: =A58-1 -> 45805 | B59: 28, | C59: 2025 | D59: 12 | E59: 2146 | F59: 9
A60: =A59-3 -> 45802 | B60: 25, | C60: 2025 | D60: 12 | E60: 2132 | F60: 18
A61: =A60-1 -> 45801 | B61: 24, | C61: 2025 | D61: 12 | E61: 2138 | F61: 17
A62: =A61-1 -> 45800 | B62: 23, | C62: 2025 | D62: 10 | E62: 2145 | F62: 15
A63: =A62-1 -> 45799 | B63: 22, | C63: 2025 | D63: 14 | E63: 2141 | F63: 10
A64: =A63-1 -> 45798 | B64: 21, | C64: 2025 | D64: 13 | E64: 2134 | F64: 5
A65: =A64-3 -> 45795 | B65: 18, | C65: 2025 | D65: 11 | E65: 2096 | F65: 14
A66: =A65-1 -> 45794 | B66: 17, | C66: 2025 | D66: 5 | E66: 2096 | F66: 13
A67: =A66-1 -> 45793 | B67: 16, | C67: 2025 | D67: 17 | E67: 2095 | F67: 12
A68: =A67-1 -> 45792 | B68: 15, | C68: 2025 | D68: 10 | E68: 2086 | F68: 10
A69: =A68-1 -> 45791 | B69: 14, | C69: 2025 | D69: 13 | E69: 2083 | F69: 5
A70: =A69-3 -> 45788 | B70: 11, | C70: 2025 | D70: 29 | E70: 2047 | F70: 6
A71: =A70-1 -> 45787 | B71: 10, | C71: 2025 | D71: 14 | E71: 2025 | F71: 18
A72: =A71-1 -> 45786 | B72: 09, | C72: 2025 | D72: 11 | E72: 2023 | F72: 14
A73: =A72-1 -> 45785 | B73: 08, | C73: 2025 | D73: 5 | E73: 2025 | F73: 6
A74: =A73-1 -> 45784 | B74: 07, | C74: 2025 | D74: 9 | E74: 2026 | F74: 7
A75: =A74-3 -> 45781 | B75: 04, | C75: 2025 | D75: 2 | E75: 2015 | F75: 14
A76: =A75-1 -> 45780 | B76: 03, | C76: 2025 | D76: 11 | E76: 2019 | F76: 10
A77: =A76-1 -> 45779 | B77: 6 | C77: 35 | D77: 9 | E77: 2020 | F77: 9
A78: =A77-1 -> 45778 | B78: 10 | C78: 29 | D78: 17 | E78: 2010 | F78: 5
A79: 45897 | B79: 8 | C79: 33 | D79: 6 | E79: 1984 | F79: 17
A80: 45896 | B80: 5 | C80: 19 | D80: 9 | E80: 1988 | F80: 19
A81: 45895 | B81: 10 | C81: 21 | D81: 20 | E81: 1989 | F81: 15
A82: 45894 | B82: 8 | C82: 30 | D82: 8 | E82: 1980 | F82: 11
...

Sheet PIVOT_TABLE
A1: Monthly Pivot Table Analysis (2023–2025)
B3: Monthly Total Children Apprehended (2023–2025) | H3: Monthly Average Children in CBP Custody (2023–2025)
B4: Sum of Children_Apprehended | C4: Column Labels | H4: Average of Children in CBP custody | I4: Column Labels
B5: Row Labels | C5: 2023 | D5: 2024 | E5: 2025 | F5: Grand Total | H5: Row Labels | I5: 2023 | J5: 2024 | K5: 2025 | L5: Grand Total
B6: Jan | C6: 247 | D6: 2097 | E6: 1311 | F6: 3655 | H6: Jan | I6: 43.875 | J6: 170.59091 | K6: 88.954545 | L6: 116.55769
B7: Feb | C7: 1886 | D7: 4517 | E7: 312 | F7: 6715 | H7: Feb | I7: 171.31579 | J7: 441.6 | K7: 22.684211 | L7: 215.82759
B8: Mar | C8: 2479 | D8: 3377 | E8: 169 | F8: 6025 | H8: Mar | I8: 245.10526 | J8: 321.19048 | K8: 21.454545 | L8: 191.51613
B9: Apr | C9: 3129 | D9: 3424 | E9: 189 | F9: 6742 | H9: Apr | I9: 250.19048 | J9: 309.18182 | K9: 24.869565 | L9: 191.33333
B10: May | C10: 2746 | D10: 3493 | E10: 233 | F10: 6472 | H10: May | I10: 216.95455 | J10: 345.7619 | K10: 1028.875 | L10: 640.83133
B11: Jun | C11: 1774 | D11: 3376 | E11: 123 | F11: 5273 | H11: Jun | I11: 145.65 | J11: 283.95238 | K11: 19.058824 | L11: 158.62069
B12: Jul | C12: 2858 | D12: 2563 | E12: 70 | F12: 5491 | H12: Jul | I12: 245.28571 | J12: 212.42857 | K12: 13.952381 | L12: 157.22222
B13: Aug | C13: 2751 | D13: 2656 | E13: 107 | F13: 5514 | H13: Aug | I13: 237.2 | J13: 254.47368 | K13: 25.6 | L13: 171.0339
B14: Sep | C14: 3194 | D14: 2783 | F14: 5977 | H14: Sep | I14: 291.05263 | J14: 239.22727 | L14: 263.2439
B15: Oct | C15: 1486 | D15: 2736 | E15: 168 | F15: 4390 | H15: Oct | I15: 102.90909 | J15: 243.42857 | K15: 34.333333 | L15: 126.51562
B16: Nov | C16: 2299 | D16: 2664 | E16: 129 | F16: 5092 | H16: Nov | I16: 183.5 | J16: 236.73684 | K16: 34.789474 | L16: 152.22414
B17: Dec | C17: 2207 | D17: 3480 | E17: 116 | F17: 5803 | H17: Dec | I17: 186.63158 | J17: 271.72727 | K17: 36.2 | L17: 179.76786
B18: Grand Total | C18: 27056 | D18: 37166 | E18: 2927 | F18: 67149 | H18: Grand Total | I18: 200.46957 | J18: 276.90438 | K18: 199.33473 | L18: 226.73889
A20: Monthly Average Children in HHS Care (2023–2025) | G20: Monthly Total Children Transferred Out of CBP Custody (2023–2025) | M20: Monthly Total Children Discharged from HHS Care (2023–2025)
A21: Average of Children in HHS Care | B21: Column Labels | G21: Sum of Children transferred out of CBP custody | H21: Column Labels | M21: Sum of Children discharged from HHS Care | N21: Column Labels
A22: Row Labels | B22: 2023 | C22: 2024 | D22: 2025 | E22: Grand Total | G22: Row Labels | H22: 2023 | I22: 2024 | J22: 2025 | K22: Grand Total | M22: Row Labels | N22: 2023 | O22: 2024 | P22: 2025 | Q22: Grand Total
A23: Jan | B23: 7369.625 | C23: 8851.0455 | D23: 4991.0909 | E23: 6990.0769 | G23: Jan | H23: 276 | I23: 2850 | J23: 1750 | K23: 4876 | M23: Jan | N23: 1856 | O23: 6496 | P23: 3330 | Q23: 11682
A24: Feb | B24: 7795.7895 | C24: 8325.2 | D24: 2781.5263 | E24: 6335.7414 | G24: Feb | H24: 2637 | I24: 6332 | J24: 341 | K24: 9310 | M24: Feb | N24: 5183 | O24: 5273 | P24: 1160 | Q24: 11616
A25: Mar | B25: 7945.3684 | C25: 8382.6667 | D25: 2164.4545 | E25: 6042.1935 | G25: Mar | H25: 3399 | I25: 5209 | J25: 190 | K25: 8798 | M25: Mar | N25: 5375 | O25: 5678 | P25: 309 | Q25: 11362
A26: Apr | B26: 7842.6667 | C26: 7027.1364 | D26: 2273.1304 | E26: 5629.9242 | G26: Apr | H26: 3967 | I26: 5178 | J26: 230 | K26: 9375 | M26: Apr | N26: 5668 | O26: 4474 | P26: 203 | Q26: 10345
A27: May | B27: 8187.1364 | C27: 7490.2857 | D27: 2228.35 | E27: 5139.1205 | G27: May | H27: 3622 | I27: 5194 | J27: 512 | K27: 9328 | M27: May | N27: 6256 | O27: 4336 | P27: 442 | Q27: 11034
A28: Jun | B28: 6136.45 | C28: 7407.5238 | D28: 2492.4118 | E28: 5528.5862 | G28: Jun | H28: 2416 | I28: 4882 | J28: 138 | K28: 7436 | M28: Jun | N28: 4029 | O28: 4911 | P28: 281 | Q28: 9221
A29: Jul | B29: 6828.0952 | C29: 6286.3333 | D29: 2187.1905 | E29: 5100.5397 | G29: Jul | H29: 3897 | I29: 3679 | J29: 88 | K29: 7664 | M29: Jul | N29: 4407 | O29: 3899 | P29: 396 | Q29: 8702
A30: Aug | B30: 9347.9 | C30: 6004.2632 | D30: 2001.3 | E30: 5780.7627 | G30: Aug | H30: 3587 | I30: 3546 | J30: 147 | K30: 7280 | M30: Aug | N30: 6470 | O30: 3073 | P30: 254 | Q30: 9797
A31: Sep | B31: 10701.316 | C31: 6213.4091 | E31: 8293.1707 | G31: Sep | H31: 3971 | I31: 3987 | K31: 7958 | M31: Sep | N31: 6546 | O31: 3692 | Q31: 10238
A32: Oct | B32: 10205.318 | C32: 6032.8571 | D32: 2231.0476 | E32: 6219.6719 | G32: Oct | H32: 2049 | I32: 3886 | J32: 263 | K32: 6198 | M32: Oct | N32: 7658 | O32: 3194 | P32: 242 | Q32: 11094
A33: Nov | B33: 9726.1 | C33: 5914.6842 | D33: 2325.8947 | E33: 6053.3276 | G33: Nov | H33: 3198 | I33: 3414 | J33: 182 | K33: 6794 | M33: Nov | N33: 5992 | O33: 3001 | P33: 159 | Q33: 9152
A34: Dec | B34: 11068.632 | C34: 6418.6818 | D34: 2445.2667 | E34: 6932.0357 | G34: Dec | H34: 3105 | I34: 4395 | J34: 124 | K34: 7624 | M34: Dec | N34: 6804 | O34: 3662 | P34: 144 | Q34: 10610
A35: Grand Total | B35: 8646.0739 | C35: 7042.9602 | D35: 2542.8368 | E35: 6061.275 | G35: Grand Total | H35: 36124 | I35: 52552 | J35: 3965 | K35: 92641 | M35: Grand Total | N35: 66244 | O35: 51689 | P35: 6920 | Q35: 124853
C37: Monthly System Capacity Overview (CBP Custody vs HHS Care) (2023–2025)
D38: Column Labels
D39: Average of Children in CBP custody | G39: Average of Children in HHS Care | J39: Total Average of Children in CBP custody | K39: Total Average of Children in HHS Care
C40: Row Labels | D40: 2023 | E40: 2024 | F40: 2025 | G40: 2023 | H40: 2024 | I40: 2025
C41: Jan | D41: 43.875 | E41: 170.59091 | F41: 88.954545 | G41: 7369.625 | H41: 8851.0455 | I41: 4991.0909 | J41: 116.55769 | K41: 6990.0769
C42: Feb | D42: 171.31579 | E42: 441.6 | F42: 22.684211 | G42: 7795.7895 | H42: 8325.2 | I42: 2781.5263 | J42: 215.82759 | K42: 6335.7414
C43: Mar | D43: 245.10526 | E43: 321.19048 | F43: 21.454545 | G43: 7945.3684 | H43: 8382.6667 | I43: 2164.4545 | J43: 191.51613 | K43: 6042.1935
...

Sheet PIVOT_CHART
A1: MONTHLY HEALTHCARE DATA ANALYSIS CHARTS (2023–2025)

Sheet DATA_ANALYSIS
C1: HEALTHCARE DATA ANALYSIS & BUSINESS INSIGHTS (2023–2025)
E3: KEY PERFORMANCE INDICATORS (KPIs)
E4: TOTAL CHILDREN UNDER CARE | F4: =SUM(CLEAN_DATA!E2:E721) -> 4364118
E5: NET INTAKE PRESSURE | F5: =F11-F15 -> -57704
E6: CARE LOAD VOLATILITY INDEX | F6: =_xlfn.STDEV.S(CLEAN_DATA!E2:E721) -> 2833.0701
E7: BACKLOG ACCUMULATION RATE | F7: =(SUM(CLEAN_DATA!B2:B721)-SUM(CLEAN_DATA!F2:F721))/COUNT(CLEAN_DATA!A2:A721) -> -80.144444
E8: DISCHARGE OFFSET RATIO | F8: =SUM(CLEAN_DATA!F2:F721)/SUM(CLEAN_DATA!B2:B721) -> 1.8593427
E10: HEALTHCARE METRICS | F10: TOTAL | G10: AVERAGE | H10: MAXIMUM | I10: MINIMUM
E11: Children Apprehended | F11: =SUM(CLEAN_DATA!B2:B721) -> 67149 | G11: =AVERAGE(CLEAN_DATA!B2:B721) -> 95.927143 | H11: =MAX(CLEAN_DATA!B2:B721) -> 333 | I11: =MIN(CLEAN_DATA!B2:B721) -> 0
E12: Children in CBP Custody | F12: =SUM(CLEAN_DATA!C2:C721) -> 163252 | G12: =AVERAGE(CLEAN_DATA!C2:C721) -> 226.73889 | H12: =MAX(CLEAN_DATA!C2:C721) -> 2025 | I12: =MIN(CLEAN_DATA!C2:C721) -> 7
E13: Children Transferred to HHS | F13: =SUM(CLEAN_DATA!D2:D721) -> 92641 | G13: =AVERAGE(CLEAN_DATA!D2:D721) -> 128.66806 | H13: =MAX(CLEAN_DATA!D2:D721) -> 440 | I13: =MIN(CLEAN_DATA!D2:D721) -> 0
E14: Children in HHS Care | F14: =SUM(CLEAN_DATA!E2:E721) -> 4364118 | G14: =AVERAGE(CLEAN_DATA!E2:E721) -> 6061.275 | H14: =MAX(CLEAN_DATA!E2:E721) -> 11516 | I14: =MIN(CLEAN_DATA!E2:E721) -> 1972
E15: Children Discharged | F15: =SUM(CLEAN_DATA!F2:F721) -> 124853 | G15: =AVERAGE(CLEAN_DATA!F2:F721) -> 173.40694 | H15: =MAX(CLEAN_DATA!F2:F721) -> 505 | I15: =MIN(CLEAN_DATA!F2:F721) -> 0
E17: BUSINESS INSIGHTS
D19: • | E19: HHS care handled over 4.36 million child-care records during the analysis period.
D20: • | E20: Daily HHS care load showed noticeable variation, reflecting changing operational demand.
D21: • | E21: Discharges exceeded apprehensions over the analysis period, indicating effective case processing.
D22: • | E22: Average children in CBP custody remained lower than HHS care, suggesting timely transfers to HHS facilities.
D23: • | E23: Monthly trends revealed fluctuations in apprehensions, highlighting periods of increased operational pressure.
D24: • | E24: The discharge offset ratio greater than 1 indicates that the system discharged more children than were newly apprehended during the study period.
